2019-05-14 14:15:53,835 INFO: Microblog startup [in D:\microblog\app\__init__.py:46]
2019-05-14 14:16:02,812 ERROR: Exception on /edit_profile [POST] [in c:\python27\lib\site-packages\flask\app.py:1761]
Traceback (most recent call last):
  File "c:\python27\lib\site-packages\flask\app.py", line 2292, in wsgi_app
    response = self.full_dispatch_request()
  File "c:\python27\lib\site-packages\flask\app.py", line 1815, in full_dispatch_request
    rv = self.handle_user_exception(e)
  File "c:\python27\lib\site-packages\flask\app.py", line 1718, in handle_user_exception
    reraise(exc_type, exc_value, tb)
  File "c:\python27\lib\site-packages\flask\app.py", line 1813, in full_dispatch_request
    rv = self.dispatch_request()
  File "c:\python27\lib\site-packages\flask\app.py", line 1799, in dispatch_request
    return self.view_functions[rule.endpoint](**req.view_args)
  File "c:\python27\lib\site-packages\flask_login\utils.py", line 261, in decorated_view
    return func(*args, **kwargs)
  File "D:\microblog\app\routes.py", line 98, in edit_profile
    db.session.commit()
  File "c:\python27\lib\site-packages\sqlalchemy\orm\scoping.py", line 162, in do
    return getattr(self.registry(), name)(*args, **kwargs)
  File "c:\python27\lib\site-packages\sqlalchemy\orm\session.py", line 1026, in commit
    self.transaction.commit()
  File "c:\python27\lib\site-packages\sqlalchemy\orm\session.py", line 493, in commit
    self._prepare_impl()
  File "c:\python27\lib\site-packages\sqlalchemy\orm\session.py", line 472, in _prepare_impl
    self.session.flush()
  File "c:\python27\lib\site-packages\sqlalchemy\orm\session.py", line 2451, in flush
    self._flush(objects)
  File "c:\python27\lib\site-packages\sqlalchemy\orm\session.py", line 2589, in _flush
    transaction.rollback(_capture_exception=True)
  File "c:\python27\lib\site-packages\sqlalchemy\util\langhelpers.py", line 68, in __exit__
    compat.reraise(exc_type, exc_value, exc_tb)
  File "c:\python27\lib\site-packages\sqlalchemy\orm\session.py", line 2549, in _flush
    flush_context.execute()
  File "c:\python27\lib\site-packages\sqlalchemy\orm\unitofwork.py", line 422, in execute
    rec.execute(self)
  File "c:\python27\lib\site-packages\sqlalchemy\orm\unitofwork.py", line 589, in execute
    uow,
  File "c:\python27\lib\site-packages\sqlalchemy\orm\persistence.py", line 236, in save_obj
    update,
  File "c:\python27\lib\site-packages\sqlalchemy\orm\persistence.py", line 978, in _emit_update_statements
    statement, multiparams
  File "c:\python27\lib\site-packages\sqlalchemy\engine\base.py", line 988, in execute
    return meth(self, multiparams, params)
  File "c:\python27\lib\site-packages\sqlalchemy\sql\elements.py", line 287, in _execute_on_connection
    return connection._execute_clauseelement(self, multiparams, params)
  File "c:\python27\lib\site-packages\sqlalchemy\engine\base.py", line 1107, in _execute_clauseelement
    distilled_params,
  File "c:\python27\lib\site-packages\sqlalchemy\engine\base.py", line 1248, in _execute_context
    e, statement, parameters, cursor, context
  File "c:\python27\lib\site-packages\sqlalchemy\engine\base.py", line 1466, in _handle_dbapi_exception
    util.raise_from_cause(sqlalchemy_exception, exc_info)
  File "c:\python27\lib\site-packages\sqlalchemy\util\compat.py", line 383, in raise_from_cause
    reraise(type(exception), exception, tb=exc_tb, cause=cause)
  File "c:\python27\lib\site-packages\sqlalchemy\engine\base.py", line 1244, in _execute_context
    cursor, statement, parameters, context
  File "c:\python27\lib\site-packages\sqlalchemy\engine\default.py", line 552, in do_execute
    cursor.execute(statement, parameters)
IntegrityError: (sqlite3.IntegrityError) UNIQUE constraint failed: user.username
[SQL: UPDATE user SET username=?, about_me=? WHERE user.id = ?]
[parameters: (u'test', u'', 3)]
(Background on this error at: http://sqlalche.me/e/gkpj)
2019-05-14 14:16:12,381 ERROR: Exception on /edit_profile [POST] [in c:\python27\lib\site-packages\flask\app.py:1761]
Traceback (most recent call last):
  File "c:\python27\lib\site-packages\flask\app.py", line 2292, in wsgi_app
    response = self.full_dispatch_request()
  File "c:\python27\lib\site-packages\flask\app.py", line 1815, in full_dispatch_request
    rv = self.handle_user_exception(e)
  File "c:\python27\lib\site-packages\flask\app.py", line 1718, in handle_user_exception
    reraise(exc_type, exc_value, tb)
  File "c:\python27\lib\site-packages\flask\app.py", line 1813, in full_dispatch_request
    rv = self.dispatch_request()
  File "c:\python27\lib\site-packages\flask\app.py", line 1799, in dispatch_request
    return self.view_functions[rule.endpoint](**req.view_args)
  File "c:\python27\lib\site-packages\flask_login\utils.py", line 261, in decorated_view
    return func(*args, **kwargs)
  File "D:\microblog\app\routes.py", line 98, in edit_profile
    db.session.commit()
  File "c:\python27\lib\site-packages\sqlalchemy\orm\scoping.py", line 162, in do
    return getattr(self.registry(), name)(*args, **kwargs)
  File "c:\python27\lib\site-packages\sqlalchemy\orm\session.py", line 1026, in commit
    self.transaction.commit()
  File "c:\python27\lib\site-packages\sqlalchemy\orm\session.py", line 493, in commit
    self._prepare_impl()
  File "c:\python27\lib\site-packages\sqlalchemy\orm\session.py", line 472, in _prepare_impl
    self.session.flush()
  File "c:\python27\lib\site-packages\sqlalchemy\orm\session.py", line 2451, in flush
    self._flush(objects)
  File "c:\python27\lib\site-packages\sqlalchemy\orm\session.py", line 2589, in _flush
    transaction.rollback(_capture_exception=True)
  File "c:\python27\lib\site-packages\sqlalchemy\util\langhelpers.py", line 68, in __exit__
    compat.reraise(exc_type, exc_value, exc_tb)
  File "c:\python27\lib\site-packages\sqlalchemy\orm\session.py", line 2549, in _flush
    flush_context.execute()
  File "c:\python27\lib\site-packages\sqlalchemy\orm\unitofwork.py", line 422, in execute
    rec.execute(self)
  File "c:\python27\lib\site-packages\sqlalchemy\orm\unitofwork.py", line 589, in execute
    uow,
  File "c:\python27\lib\site-packages\sqlalchemy\orm\persistence.py", line 236, in save_obj
    update,
  File "c:\python27\lib\site-packages\sqlalchemy\orm\persistence.py", line 978, in _emit_update_statements
    statement, multiparams
  File "c:\python27\lib\site-packages\sqlalchemy\engine\base.py", line 988, in execute
    return meth(self, multiparams, params)
  File "c:\python27\lib\site-packages\sqlalchemy\sql\elements.py", line 287, in _execute_on_connection
    return connection._execute_clauseelement(self, multiparams, params)
  File "c:\python27\lib\site-packages\sqlalchemy\engine\base.py", line 1107, in _execute_clauseelement
    distilled_params,
  File "c:\python27\lib\site-packages\sqlalchemy\engine\base.py", line 1248, in _execute_context
    e, statement, parameters, cursor, context
  File "c:\python27\lib\site-packages\sqlalchemy\engine\base.py", line 1466, in _handle_dbapi_exception
    util.raise_from_cause(sqlalchemy_exception, exc_info)
  File "c:\python27\lib\site-packages\sqlalchemy\util\compat.py", line 383, in raise_from_cause
    reraise(type(exception), exception, tb=exc_tb, cause=cause)
  File "c:\python27\lib\site-packages\sqlalchemy\engine\base.py", line 1244, in _execute_context
    cursor, statement, parameters, context
  File "c:\python27\lib\site-packages\sqlalchemy\engine\default.py", line 552, in do_execute
    cursor.execute(statement, parameters)
IntegrityError: (sqlite3.IntegrityError) UNIQUE constraint failed: user.username
[SQL: UPDATE user SET username=?, about_me=? WHERE user.id = ?]
[parameters: (u'test', u'', 3)]
(Background on this error at: http://sqlalche.me/e/gkpj)
2019-05-14 14:22:33,436 INFO: Microblog startup [in D:\microblog\app\__init__.py:46]
2019-05-14 14:32:42,719 INFO: Microblog startup [in D:\microblog\app\__init__.py:46]
2019-05-14 14:32:51,247 INFO: Microblog startup [in D:\microblog\app\__init__.py:46]
2019-05-14 14:45:47,836 INFO: Microblog startup [in D:\microblog\app\__init__.py:46]
2019-05-14 14:50:16,645 INFO: Microblog startup [in D:\microblog\app\__init__.py:46]
2019-05-14 15:03:36,730 INFO: Microblog startup [in D:\microblog\app\__init__.py:46]
2019-05-14 15:06:00,641 INFO: Microblog startup [in D:\microblog\app\__init__.py:46]
2019-05-14 15:13:41,993 INFO: Microblog startup [in D:\microblog\app\__init__.py:46]
2019-05-14 15:22:02,519 INFO: Microblog startup [in D:\microblog\app\__init__.py:46]
2019-05-14 15:27:39,701 INFO: Microblog startup [in D:\microblog\app\__init__.py:49]
2019-05-14 15:47:09,151 INFO: Microblog startup [in D:\microblog\app\__init__.py:49]
2019-05-14 16:02:28,665 INFO: Microblog startup [in D:\microblog\app\__init__.py:51]
